Workbook

Sheet 00_Cover
B2: Northline Consumer Products
B3: Margin & Mix Bridge — SKU × Channel Contribution | Price-Volume-Mix | Gross Margin Walk
B5: Purpose
B6: Explain how gross margin dollars moved between prior and current period: volume growth, net price, SKU/channel mix, and cost. Built for an FP&A screen-share — change yellow inputs on 01_Assumptions and watch the bridge update.
B8: How to read this file
B9: 1. Yellow fill + blue font = inputs. Black font = formulas. No VBA.
B10: 2. Start on 01_Assumptions (close period, channel list, SKU economics, prior/current volume & price).
B11: 3. 02_Volume_Price builds SKU×channel revenue and contribution.
B12: 4. 03_PVM_Bridge walks Prior GM → Volume → Price → Mix → Cost → Current GM (revenue and GM$).
B13: 5. 04_Contribution shows margin by SKU and by channel with mix %.
B14: 6. 05_Dashboard is the one-pager for leadership: GM walk, mix callouts, RAG on margin %.
B15: 7. Amounts in $000s where labeled; volume in 000 units; prices and COGS in $ per unit.
... B26: Sai Siri Bandaru — Financial Analyst | FP&A

Sheet 01_Assumptions
B2: Assumptions & Inputs
B3: Yellow / blue = editable inputs. All downstream tabs reference this sheet.
B5: Close period | C5: FY26 Q2 vs FY26 Q1
B6: Units | C6: 000 cases / units
B7: Currency | C7: $000s (revenue, GM); $/unit (price, COGS)
B9: Channels
B10: Channel | C10: Role in mix story
B11: Grocery | C11: Highest net price; volume soft in current
B12: Mass | C12: Slight discount vs Grocery; mild price pressure
B13: Club | C13: Lowest net $/unit; volume surge dilutes mix
B14: E-comm | C14: Slight premium; growing but smaller base
B16: SKU list & standard COGS $/unit
B17: SKU | C17: Std COGS $/unit | D17: Category note
B18: Sparkle Water 12pk | C18: 2.15 | D18: Sparkling beverage — high velocity
B19: Protein Bar 12ct | C19: 4.85 | D19: Nutrition — mid-high margin
B20: Crunch Chips Family | C20: 1.9 | D20: Salty snacks — volume driver
B21: Clean Wipe Refill | C21: 3.35 | D21: Household — steady
B22: SoftSoap 3pk | C22: 2.5 | D22: Personal care — promotional
B23: Multipack Snacks | C23: 5.1 | D23: Club-oriented pack — thin margin
B25: Prior-period volume (000 units) by SKU × channel
B26: SKU | C26: Grocery | D26: Mass | E26: Club | F26: E-comm | G26: Total
B27: Sparkle Water 12pk | C27: 420 | D27: 310 | E27: 180 | F27: 95 | G27: =SUM(C27:F27)
B28: Protein Bar 12ct | C28: 210 | D28: 165 | E28: 90 | F28: 70 | G28: =SUM(C28:F28)
B29: Crunch Chips Family | C29: 380 | D29: 290 | E29: 220 | F29: 85 | G29: =SUM(C29:F29)
B30: Clean Wipe Refill | C30: 145 | D30: 120 | E30: 60 | F30: 55 | G30: =SUM(C30:F30)
B31: SoftSoap 3pk | C31: 260 | D31: 240 | E31: 110 | F31: 60 | G31: =SUM(C31:F31)
B32: Multipack Snacks | C32: 80 | D32: 70 | E32: 200 | F32: 40 | G32: =SUM(C32:F32)
B33: Total | C33: =SUM(C27:C32) | D33: =SUM(D27:D32) | E33: =SUM(E27:E32) | F33: =SUM(F27:F32) | G33: =SUM(G27:G32)
B35: Current-period volume (000 units) by SKU × channel
B36: SKU | C36: Grocery | D36: Mass | E36: Club | F36: E-comm | G36: Total
B37: Sparkle Water 12pk | C37: 360 | D37: 280 | E37: 280 | F37: 105 | G37: =SUM(C37:F37)
B38: Protein Bar 12ct | C38: 185 | D38: 150 | E38: 150 | F38: 80 | G38: =SUM(C38:F38)
B39: Crunch Chips Family | C39: 320 | D39: 250 | E39: 340 | F39: 95 | G39: =SUM(C39:F39)
B40: Clean Wipe Refill | C40: 130 | D40: 110 | E40: 95 | F40: 60 | G40: =SUM(C40:F40)
B41: SoftSoap 3pk | C41: 220 | D41: 210 | E41: 175 | F41: 65 | G41: =SUM(C41:F41)
B42: Multipack Snacks | C42: 60 | D42: 55 | E42: 340 | F42: 45 | G42: =SUM(C42:F42)
B43: Total | C43: =SUM(C37:C42) | D43: =SUM(D37:D42) | E43: =SUM(E37:E42) | F43: =SUM(F37:F42) | G43: =SUM(G37:G42)
B45: Prior-period net price ($/unit) by SKU × channel
B46: SKU | C46: Grocery | D46: Mass | E46: Club | F46: E-comm
B47: Sparkle Water 12pk | C47: 5.49 | D47: 5.29 | E47: 4.49 | F47: 5.69
...

Sheet 02_Volume_Price
B2: Volume, Price & Contribution Build | P2: KPI anchors (for bridge)
B3: SKU×channel detail. Revenue and GM in $000s (= volume 000 × $/unit). | P3: Rev Prior $000 | Q3: =J30
P4: Rev Curr $000 | Q4: =K30
B5: SKU | C5: Channel | D5: Vol Prior | E5: Vol Curr | F5: Δ Vol | G5: Price Prior | H5: Price Curr | I5: Δ Price | J5: Rev Prior $000 | K5: Rev Curr $000 | L5: COGS $/u | M5: GM Prior $000 | N5: GM Curr $000 | P5: GM Prior $000 | Q5: =M30
B6: Sparkle Water 12pk | C6: Grocery | D6: ='01_Assumptions'!C27 | E6: ='01_Assumptions'!C37 | F6: =E6-D6 | G6: ='01_Assumptions'!C47 | H6: ='01_Assumptions'!C56 | I6: =H6-G6 | J6: =D6*G6 | K6: =E6*H6 | L6: ='01_Assumptions'!C18 | M6: =D6*(G6-L6) | N6: =E6*(H6-L6) | P6: GM Curr $000 | Q6: =N30
B7: Sparkle Water 12pk | C7: Mass | D7: ='01_Assumptions'!D27 | E7: ='01_Assumptions'!D37 | F7: =E7-D7 | G7: ='01_Assumptions'!D47 | H7: ='01_Assumptions'!D56 | I7: =H7-G7 | J7: =D7*G7 | K7: =E7*H7 | L7: ='01_Assumptions'!C18 | M7: =D7*(G7-L7) | N7: =E7*(H7-L7) | P7: Vol Prior 000 | Q7: =D30
B8: Sparkle Water 12pk | C8: Club | D8: ='01_Assumptions'!E27 | E8: ='01_Assumptions'!E37 | F8: =E8-D8 | G8: ='01_Assumptions'!E47 | H8: ='01_Assumptions'!E56 | I8: =H8-G8 | J8: =D8*G8 | K8: =E8*H8 | L8: ='01_Assumptions'!C18 | M8: =D8*(G8-L8) | N8: =E8*(H8-L8) | P8: Vol Curr 000 | Q8: =E30
B9: Sparkle Water 12pk | C9: E-comm | D9: ='01_Assumptions'!F27 | E9: ='01_Assumptions'!F37 | F9: =E9-D9 | G9: ='01_Assumptions'!F47 | H9: ='01_Assumptions'!F56 | I9: =H9-G9 | J9: =D9*G9 | K9: =E9*H9 | L9: ='01_Assumptions'!C18 | M9: =D9*(G9-L9) | N9: =E9*(H9-L9)
B10: Protein Bar 12ct | C10: Grocery | D10: ='01_Assumptions'!C28 | E10: ='01_Assumptions'!C38 | F10: =E10-D10 | G10: ='01_Assumptions'!C48 | H10: ='01_Assumptions'!C57 | I10: =H10-G10 | J10: =D10*G10 | K10: =E10*H10 | L10: ='01_Assumptions'!C19 | M10: =D10*(G10-L10) | N10: =E10*(H10-L10)
B11: Protein Bar 12ct | C11: Mass | D11: ='01_Assumptions'!D28 | E11: ='01_Assumptions'!D38 | F11: =E11-D11 | G11: ='01_Assumptions'!D48 | H11: ='01_Assumptions'!D57 | I11: =H11-G11 | J11: =D11*G11 | K11: =E11*H11 | L11: ='01_Assumptions'!C19 | M11: =D11*(G11-L11) | N11: =E11*(H11-L11)
B12: Protein Bar 12ct | C12: Club | D12: ='01_Assumptions'!E28 | E12: ='01_Assumptions'!E38 | F12: =E12-D12 | G12: ='01_Assumptions'!E48 | H12: ='01_Assumptions'!E57 | I12: =H12-G12 | J12: =D12*G12 | K12: =E12*H12 | L12: ='01_Assumptions'!C19 | M12: =D12*(G12-L12) | N12: =E12*(H12-L12)
B13: Protein Bar 12ct | C13: E-comm | D13: ='01_Assumptions'!F28 | E13: ='01_Assumptions'!F38 | F13: =E13-D13 | G13: ='01_Assumptions'!F48 | H13: ='01_Assumptions'!F57 | I13: =H13-G13 | J13: =D13*G13 | K13: =E13*H13 | L13: ='01_Assumptions'!C19 | M13: =D13*(G13-L13) | N13: =E13*(H13-L13)
B14: Crunch Chips Family | C14: Grocery | D14: ='01_Assumptions'!C29 | E14: ='01_Assumptions'!C39 | F14: =E14-D14 | G14: ='01_Assumptions'!C49 | H14: ='01_Assumptions'!C58 | I14: =H14-G14 | J14: =D14*G14 | K14: =E14*H14 | L14: ='01_Assumptions'!C20 | M14: =D14*(G14-L14) | N14: =E14*(H14-L14)
B15: Crunch Chips Family | C15: Mass | D15: ='01_Assumptions'!D29 | E15: ='01_Assumptions'!D39 | F15: =E15-D15 | G15: ='01_Assumptions'!D49 | H15: ='01_Assumptions'!D58 | I15: =H15-G15 | J15: =D15*G15 | K15: =E15*H15 | L15: ='01_Assumptions'!C20 | M15: =D15*(G15-L15) | N15: =E15*(H15-L15)
B16: Crunch Chips Family | C16: Club | D16: ='01_Assumptions'!E29 | E16: ='01_Assumptions'!E39 | F16: =E16-D16 | G16: ='01_Assumptions'!E49 | H16: ='01_Assumptions'!E58 | I16: =H16-G16 | J16: =D16*G16 | K16: =E16*H16 | L16: ='01_Assumptions'!C20 | M16: =D16*(G16-L16) | N16: =E16*(H16-L16)
B17: Crunch Chips Family | C17: E-comm | D17: ='01_Assumptions'!F29 | E17: ='01_Assumptions'!F39 | F17: =E17-D17 | G17: ='01_Assumptions'!F49 | H17: ='01_Assumptions'!F58 | I17: =H17-G17 | J17: =D17*G17 | K17: =E17*H17 | L17: ='01_Assumptions'!C20 | M17: =D17*(G17-L17) | N17: =E17*(H17-L17)
B18: Clean Wipe Refill | C18: Grocery | D18: ='01_Assumptions'!C30 | E18: ='01_Assumptions'!C40 | F18: =E18-D18 | G18: ='01_Assumptions'!C50 | H18: ='01_Assumptions'!C59 | I18: =H18-G18 | J18: =D18*G18 | K18: =E18*H18 | L18: ='01_Assumptions'!C21 | M18: =D18*(G18-L18) | N18: =E18*(H18-L18)
B19: Clean Wipe Refill | C19: Mass | D19: ='01_Assumptions'!D30 | E19: ='01_Assumptions'!D40 | F19: =E19-D19 | G19: ='01_Assumptions'!D50 | H19: ='01_Assumptions'!D59 | I19: =H19-G19 | J19: =D19*G19 | K19: =E19*H19 | L19: ='01_Assumptions'!C21 | M19: =D19*(G19-L19) | N19: =E19*(H19-L19)
B20: Clean Wipe Refill | C20: Club | D20: ='01_Assumptions'!E30 | E20: ='01_Assumptions'!E40 | F20: =E20-D20 | G20: ='01_Assumptions'!E50 | H20: ='01_Assumptions'!E59 | I20: =H20-G20 | J20: =D20*G20 | K20: =E20*H20 | L20: ='01_Assumptions'!C21 | M20: =D20*(G20-L20) | N20: =E20*(H20-L20)
B21: Clean Wipe Refill | C21: E-comm | D21: ='01_Assumptions'!F30 | E21: ='01_Assumptions'!F40 | F21: =E21-D21 | G21: ='01_Assumptions'!F50 | H21: ='01_Assumptions'!F59 | I21: =H21-G21 | J21: =D21*G21 | K21: =E21*H21 | L21: ='01_Assumptions'!C21 | M21: =D21*(G21-L21) | N21: =E21*(H21-L21)
B22: SoftSoap 3pk | C22: Grocery | D22: ='01_Assumptions'!C31 | E22: ='01_Assumptions'!C41 | F22: =E22-D22 | G22: ='01_Assumptions'!C51 | H22: ='01_Assumptions'!C60 | I22: =H22-G22 | J22: =D22*G22 | K22: =E22*H22 | L22: ='01_Assumptions'!C22 | M22: =D22*(G22-L22) | N22: =E22*(H22-L22)
B23: SoftSoap 3pk | C23: Mass | D23: ='01_Assumptions'!D31 | E23: ='01_Assumptions'!D41 | F23: =E23-D23 | G23: ='01_Assumptions'!D51 | H23: ='01_Assumptions'!D60 | I23: =H23-G23 | J23: =D23*G23 | K23: =E23*H23 | L23: ='01_Assumptions'!C22 | M23: =D23*(G23-L23) | N23: =E23*(H23-L23)
B24: SoftSoap 3pk | C24: Club | D24: ='01_Assumptions'!E31 | E24: ='01_Assumptions'!E41 | F24: =E24-D24 | G24: ='01_Assumptions'!E51 | H24: ='01_Assumptions'!E60 | I24: =H24-G24 | J24: =D24*G24 | K24: =E24*H24 | L24: ='01_Assumptions'!C22 | M24: =D24*(G24-L24) | N24: =E24*(H24-L24)
B25: SoftSoap 3pk | C25: E-comm | D25: ='01_Assumptions'!F31 | E25: ='01_Assumptions'!F41 | F25: =E25-D25 | G25: ='01_Assumptions'!F51 | H25: ='01_Assumptions'!F60 | I25: =H25-G25 | J25: =D25*G25 | K25: =E25*H25 | L25: ='01_Assumptions'!C22 | M25: =D25*(G25-L25) | N25: =E25*(H25-L25)
B26: Multipack Snacks | C26: Grocery | D26: ='01_Assumptions'!C32 | E26: ='01_Assumptions'!C42 | F26: =E26-D26 | G26: ='01_Assumptions'!C52 | H26: ='01_Assumptions'!C61 | I26: =H26-G26 | J26: =D26*G26 | K26: =E26*H26 | L26: ='01_Assumptions'!C23 | M26: =D26*(G26-L26) | N26: =E26*(H26-L26)
B27: Multipack Snacks | C27: Mass | D27: ='01_Assumptions'!D32 | E27: ='01_Assumptions'!D42 | F27: =E27-D27 | G27: ='01_Assumptions'!D52 | H27: ='01_Assumptions'!D61 | I27: =H27-G27 | J27: =D27*G27 | K27: =E27*H27 | L27: ='01_Assumptions'!C23 | M27: =D27*(G27-L27) | N27: =E27*(H27-L27)
B28: Multipack Snacks | C28: Club | D28: ='01_Assumptions'!E32 | E28: ='01_Assumptions'!E42 | F28: =E28-D28 | G28: ='01_Assumptions'!E52 | H28: ='01_Assumptions'!E61 | I28: =H28-G28 | J28: =D28*G28 | K28: =E28*H28 | L28: ='01_Assumptions'!C23 | M28: =D28*(G28-L28) | N28: =E28*(H28-L28)
B29: Multipack Snacks | C29: E-comm | D29: ='01_Assumptions'!F32 | E29: ='01_Assumptions'!F42 | F29: =E29-D29 | G29: ='01_Assumptions'!F52 | H29: ='01_Assumptions'!F61 | I29: =H29-G29 | J29: =D29*G29 | K29: =E29*H29 | L29: ='01_Assumptions'!C23 | M29: =D29*(G29-L29) | N29: =E29*(H29-L29)
B30: TOTAL | D30: =SUM(D6:D29) | E30: =SUM(E6:E29) | F30: =SUM(F6:F29) | J30: =SUM(J6:J29) | K30: =SUM(K6:K29) | M30: =SUM(M6:M29) | N30: =SUM(N6:N29)
B33: Summary by SKU
B34: SKU | C34: Vol Prior | D34: Vol Curr | E34: Rev Prior | F34: Rev Curr | G34: GM Prior | H34: GM Curr | I34: GM% Prior | J34: GM% Curr
B35: Sparkle Water 12pk | C35: =SUMIF($B$6:$B$29,B35,$D$6:$D$29) | D35: =SUMIF($B$6:$B$29,B35,$E$6:$E$29) | E35: =SUMIF($B$6:$B$29,B35,$J$6:$J$29) | F35: =SUMIF($B$6:$B$29,B35,$K$6:$K$29) | G35: =SUMIF($B$6:$B$29,B35,$M$6:$M$29) | H35: =SUMIF($B$6:$B$29,B35,$N$6:$N$29) | I35: =IF(E35=0,0,G35/E35) | J35: =IF(F35=0,0,H35/F35)
B36: Protein Bar 12ct | C36: =SUMIF($B$6:$B$29,B36,$D$6:$D$29) | D36: =SUMIF($B$6:$B$29,B36,$E$6:$E$29) | E36: =SUMIF($B$6:$B$29,B36,$J$6:$J$29) | F36: =SUMIF($B$6:$B$29,B36,$K$6:$K$29) | G36: =SUMIF($B$6:$B$29,B36,$M$6:$M$29) | H36: =SUMIF($B$6:$B$29,B36,$N$6:$N$29) | I36: =IF(E36=0,0,G36/E36) | J36: =IF(F36=0,0,H36/F36)
B37: Crunch Chips Family | C37: =SUMIF($B$6:$B$29,B37,$D$6:$D$29) | D37: =SUMIF($B$6:$B$29,B37,$E$6:$E$29) | E37: =SUMIF($B$6:$B$29,B37,$J$6:$J$29) | F37: =SUMIF($B$6:$B$29,B37,$K$6:$K$29) | G37: =SUMIF($B$6:$B$29,B37,$M$6:$M$29) | H37: =SUMIF($B$6:$B$29,B37,$N$6:$N$29) | I37: =IF(E37=0,0,G37/E37) | J37: =IF(F37=0,0,H37/F37)
B38: Clean Wipe Refill | C38: =SUMIF($B$6:$B$29,B38,$D$6:$D$29) | D38: =SUMIF($B$6:$B$29,B38,$E$6:$E$29) | E38: =SUMIF($B$6:$B$29,B38,$J$6:$J$29) | F38: =SUMIF($B$6:$B$29,B38,$K$6:$K$29) | G38: =SUMIF($B$6:$B$29,B38,$M$6:$M$29) | H38: =SUMIF($B$6:$B$29,B38,$N$6:$N$29) | I38: =IF(E38=0,0,G38/E38) | J38: =IF(F38=0,0,H38/F38)
B39: SoftSoap 3pk | C39: =SUMIF($B$6:$B$29,B39,$D$6:$D$29) | D39: =SUMIF($B$6:$B$29,B39,$E$6:$E$29) | E39: =SUMIF($B$6:$B$29,B39,$J$6:$J$29) | F39: =SUMIF($B$6:$B$29,B39,$K$6:$K$29) | G39: =SUMIF($B$6:$B$29,B39,$M$6:$M$29) | H39: =SUMIF($B$6:$B$29,B39,$N$6:$N$29) | I39: =IF(E39=0,0,G39/E39) | J39: =IF(F39=0,0,H39/F39)
B40: Multipack Snacks | C40: =SUMIF($B$6:$B$29,B40,$D$6:$D$29) | D40: =SUMIF($B$6:$B$29,B40,$E$6:$E$29) | E40: =SUMIF($B$6:$B$29,B40,$J$6:$J$29) | F40: =SUMIF($B$6:$B$29,B40,$K$6:$K$29) | G40: =SUMIF($B$6:$B$29,B40,$M$6:$M$29) | H40: =SUMIF($B$6:$B$29,B40,$N$6:$N$29) | I40: =IF(E40=0,0,G40/E40) | J40: =IF(F40=0,0,H40/F40)
B41: Total | C41: =SUM(C35:C40) | D41: =SUM(D35:D40) | E41: =SUM(E35:E40) | F41: =SUM(F35:F40) | G41: =SUM(G35:G40) | H41: =SUM(H35:H40) | I41: =IF(E41=0,0,G41/E41) | J41: =IF(F41=0,0,H41/F41)
B44: Summary by Channel
B45: Channel | C45: Vol Prior | D45: Vol Curr | E45: Rev Prior | F45: Rev Curr | G45: GM Prior | H45: GM Curr | I45: GM% Prior | J45: GM% Curr | K45: Vol Mix% Prior | L45: Vol Mix% Curr
...

Sheet 03_PVM_Bridge
B2: Price / Volume / Mix Bridge
B3: Decomposition of revenue and gross margin $ from prior → current. Volume at prior mix & prior price/margin; Price on current volume; Mix = residual mix shift; Cost = COGS/unit change (≈0 here).
B5: A. Line-level components (SKU × channel)
B6: SKU | C6: Channel | D6: V0 | E6: V1 | F6: P0 | G6: P1 | H6: C | I6: Rev0 | J6: Rev1 | K6: GM0 | L6: GM1 | M6: V1*P0 | N6: V1*m0 | O6: Price_Rev | P6: Price_GM | Q6: Cost_GM
B7: ='02_Volume_Price'!B6 | C7: ='02_Volume_Price'!C6 | D7: ='02_Volume_Price'!D6 | E7: ='02_Volume_Price'!E6 | F7: ='02_Volume_Price'!G6 | G7: ='02_Volume_Price'!H6 | H7: ='02_Volume_Price'!L6 | I7: =D7*F7 | J7: =E7*G7 | K7: =D7*(F7-H7) | L7: =E7*(G7-H7) | M7: =E7*F7 | N7: =E7*(F7-H7) | O7: =E7*(G7-F7) | P7: =E7*(G7-F7) | Q7: =E7*0
B8: ='02_Volume_Price'!B7 | C8: ='02_Volume_Price'!C7 | D8: ='02_Volume_Price'!D7 | E8: ='02_Volume_Price'!E7 | F8: ='02_Volume_Price'!G7 | G8: ='02_Volume_Price'!H7 | H8: ='02_Volume_Price'!L7 | I8: =D8*F8 | J8: =E8*G8 | K8: =D8*(F8-H8) | L8: =E8*(G8-H8) | M8: =E8*F8 | N8: =E8*(F8-H8) | O8: =E8*(G8-F8) | P8: =E8*(G8-F8) | Q8: =E8*0
B9: ='02_Volume_Price'!B8 | C9: ='02_Volume_Price'!C8 | D9: ='02_Volume_Price'!D8 | E9: ='02_Volume_Price'!E8 | F9: ='02_Volume_Price'!G8 | G9: ='02_Volume_Price'!H8 | H9: ='02_Volume_Price'!L8 | I9: =D9*F9 | J9: =E9*G9 | K9: =D9*(F9-H9) | L9: =E9*(G9-H9) | M9: =E9*F9 | N9: =E9*(F9-H9) | O9: =E9*(G9-F9) | P9: =E9*(G9-F9) | Q9: =E9*0
B10: ='02_Volume_Price'!B9 | C10: ='02_Volume_Price'!C9 | D10: ='02_Volume_Price'!D9 | E10: ='02_Volume_Price'!E9 | F10: ='02_Volume_Price'!G9 | G10: ='02_Volume_Price'!H9 | H10: ='02_Volume_Price'!L9 | I10: =D10*F10 | J10: =E10*G10 | K10: =D10*(F10-H10) | L10: =E10*(G10-H10) | M10: =E10*F10 | N10: =E10*(F10-H10) | O10: =E10*(G10-F10) | P10: =E10*(G10-F10) | Q10: =E10*0
B11: ='02_Volume_Price'!B10 | C11: ='02_Volume_Price'!C10 | D11: ='02_Volume_Price'!D10 | E11: ='02_Volume_Price'!E10 | F11: ='02_Volume_Price'!G10 | G11: ='02_Volume_Price'!H10 | H11: ='02_Volume_Price'!L10 | I11: =D11*F11 | J11: =E11*G11 | K11: =D11*(F11-H11) | L11: =E11*(G11-H11) | M11: =E11*F11 | N11: =E11*(F11-H11) | O11: =E11*(G11-F11) | P11: =E11*(G11-F11) | Q11: =E11*0
B12: ='02_Volume_Price'!B11 | C12: ='02_Volume_Price'!C11 | D12: ='02_Volume_Price'!D11 | E12: ='02_Volume_Price'!E11 | F12: ='02_Volume_Price'!G11 | G12: ='02_Volume_Price'!H11 | H12: ='02_Volume_Price'!L11 | I12: =D12*F12 | J12: =E12*G12 | K12: =D12*(F12-H12) | L12: =E12*(G12-H12) | M12: =E12*F12 | N12: =E12*(F12-H12) | O12: =E12*(G12-F12) | P12: =E12*(G12-F12) | Q12: =E12*0
B13: ='02_Volume_Price'!B12 | C13: ='02_Volume_Price'!C12 | D13: ='02_Volume_Price'!D12 | E13: ='02_Volume_Price'!E12 | F13: ='02_Volume_Price'!G12 | G13: ='02_Volume_Price'!H12 | H13: ='02_Volume_Price'!L12 | I13: =D13*F13 | J13: =E13*G13 | K13: =D13*(F13-H13) | L13: =E13*(G13-H13) | M13: =E13*F13 | N13: =E13*(F13-H13) | O13: =E13*(G13-F13) | P13: =E13*(G13-F13) | Q13: =E13*0
B14: ='02_Volume_Price'!B13 | C14: ='02_Volume_Price'!C13 | D14: ='02_Volume_Price'!D13 | E14: ='02_Volume_Price'!E13 | F14: ='02_Volume_Price'!G13 | G14: ='02_Volume_Price'!H13 | H14: ='02_Volume_Price'!L13 | I14: =D14*F14 | J14: =E14*G14 | K14: =D14*(F14-H14) | L14: =E14*(G14-H14) | M14: =E14*F14 | N14: =E14*(F14-H14) | O14: =E14*(G14-F14) | P14: =E14*(G14-F14) | Q14: =E14*0
B15: ='02_Volume_Price'!B14 | C15: ='02_Volume_Price'!C14 | D15: ='02_Volume_Price'!D14 | E15: ='02_Volume_Price'!E14 | F15: ='02_Volume_Price'!G14 | G15: ='02_Volume_Price'!H14 | H15: ='02_Volume_Price'!L14 | I15: =D15*F15 | J15: =E15*G15 | K15: =D15*(F15-H15) | L15: =E15*(G15-H15) | M15: =E15*F15 | N15: =E15*(F15-H15) | O15: =E15*(G15-F15) | P15: =E15*(G15-F15) | Q15: =E15*0
B16: ='02_Volume_Price'!B15 | C16: ='02_Volume_Price'!C15 | D16: ='02_Volume_Price'!D15 | E16: ='02_Volume_Price'!E15 | F16: ='02_Volume_Price'!G15 | G16: ='02_Volume_Price'!H15 | H16: ='02_Volume_Price'!L15 | I16: =D16*F16 | J16: =E16*G16 | K16: =D16*(F16-H16) | L16: =E16*(G16-H16) | M16: =E16*F16 | N16: =E16*(F16-H16) | O16: =E16*(G16-F16) | P16: =E16*(G16-F16) | Q16: =E16*0
B17: ='02_Volume_Price'!B16 | C17: ='02_Volume_Price'!C16 | D17: ='02_Volume_Price'!D16 | E17: ='02_Volume_Price'!E16 | F17: ='02_Volume_Price'!G16 | G17: ='02_Volume_Price'!H16 | H17: ='02_Volume_Price'!L16 | I17: =D17*F17 | J17: =E17*G17 | K17: =D17*(F17-H17) | L17: =E17*(G17-H17) | M17: =E17*F17 | N17: =E17*(F17-H17) | O17: =E17*(G17-F17) | P17: =E17*(G17-F17) | Q17: =E17*0
B18: ='02_Volume_Price'!B17 | C18: ='02_Volume_Price'!C17 | D18: ='02_Volume_Price'!D17 | E18: ='02_Volume_Price'!E17 | F18: ='02_Volume_Price'!G17 | G18: ='02_Volume_Price'!H17 | H18: ='02_Volume_Price'!L17 | I18: =D18*F18 | J18: =E18*G18 | K18: =D18*(F18-H18) | L18: =E18*(G18-H18) | M18: =E18*F18 | N18: =E18*(F18-H18) | O18: =E18*(G18-F18) | P18: =E18*(G18-F18) | Q18: =E18*0
... B30: ='02_Volume_Price'!B29 | C30: ='02_Volume_Price'!C29 | D30: ='02_Volume_Price'!D29 | E30: ='02_Volume_Price'!E29 | F30: ='02_Volume_Price'!G29 | G30: ='02_Volume_Price'!H29 | H30: ='02_Volume_Price'!L29 | I30: =D30*F30 | J30: =E30*G30 | K30: =D30*(F30-H30) | L30: =E30*(G30-H30) | M30: =E30*F30 | N30: =E30*(F30-H30) | O30: =E30*(G30-F30) | P30: =E30*(G30-F30) | Q30: =E30*0
B31: TOTAL | D31: =SUM(D7:D30) | E31: =SUM(E7:E30) | I31: =SUM(I7:I30) | J31: =SUM(J7:J30) | K31: =SUM(K7:K30) | L31: =SUM(L7:L30) | M31: =SUM(M7:M30) | N31: =SUM(N7:N30) | O31: =SUM(O7:O30) | P31: =SUM(P7:P30) | Q31: =SUM(Q7:Q30)
B33: B. Bridge math (totals)
B34: Total V0 | C34: =D31
B35: Total V1 | C35: =E31
B36: Blended P0 (Rev0/V0) | C36: =IF(C34=0,0,I31/C34)
B37: Blended m0 (GM0/V0) | C37: =IF(C34=0,0,K31/C34)
B39: Volume effect — Revenue | C39: =(C35-C34)*C36 | D39: (V1−V0) × blended prior price
B40: Price effect — Revenue | C40: =O31 | D40: Σ V1 × (P1−P0)
B41: Mix effect — Revenue | C41: =M31-I31-C39 | D41: Σ V1×P0 − Rev0 − Volume effect
B42: Check: Δ Revenue | C42: =J31-I31
B43: Check: Vol+Price+Mix | C43: =C39+C40+C41
B45: Volume effect — GM $ | C45: =(C35-C34)*C37 | D45: (V1−V0) × blended prior margin/unit
B46: Price effect — GM $ | C46: =P31 | D46: Σ V1 × (P1−P0) [COGS fixed → same as rev price]
B47: Mix effect — GM $ | C47: =N31-K31-C45 | D47: Σ V1×m0 − GM0 − Volume effect
B48: Cost effect — GM $ | C48: =Q31 | D48: Σ V1 × (C0−C1) ≈ 0 in this sample
B49: Check: Δ GM $ | C49: =L31-K31
B50: Check: Vol+Price+Mix+Cost | C50: =C45+C46+C47+C48
B52: C. Revenue bridge (prior → current)
B53: Step | C53: $000s | D53: Notes
B54: Prior Revenue | C54: =I31 | D54: Starting point
B55: (+) Volume | C55: =C39 | D55: Units up at prior blended price
B56: (+/-) Price | C56: =C40 | D56: Net price pressure on current volume
B57: (+/-) Mix | C57: =C41 | D57: Shift toward lower-price Club / Multipack
...

Sheet 04_Contribution
B2: Contribution Margin by SKU & Channel
B3: Contribution = Net revenue − Std COGS. Mix % of volume and revenue for prior and current.
B5: By SKU (current period focus)
B6: SKU | C6: Vol Curr | D6: Vol Mix % | E6: Rev Curr $000 | F6: Rev Mix % | G6: GM Curr $000 | H6: GM Mix % | I6: GM % | J6: Δ Vol vs Prior | K6: Δ GM $ vs Prior
B7: Sparkle Water 12pk | C7: ='02_Volume_Price'!D35 | D7: =C7/$C$13 | E7: ='02_Volume_Price'!F35 | F7: =E7/$E$13 | G7: ='02_Volume_Price'!H35 | H7: =G7/$G$13 | I7: ='02_Volume_Price'!J35 | J7: ='02_Volume_Price'!D35-'02_Volume_Price'!C35 | K7: ='02_Volume_Price'!H35-'02_Volume_Price'!G35
B8: Protein Bar 12ct | C8: ='02_Volume_Price'!D36 | D8: =C8/$C$13 | E8: ='02_Volume_Price'!F36 | F8: =E8/$E$13 | G8: ='02_Volume_Price'!H36 | H8: =G8/$G$13 | I8: ='02_Volume_Price'!J36 | J8: ='02_Volume_Price'!D36-'02_Volume_Price'!C36 | K8: ='02_Volume_Price'!H36-'02_Volume_Price'!G36
B9: Crunch Chips Family | C9: ='02_Volume_Price'!D37 | D9: =C9/$C$13 | E9: ='02_Volume_Price'!F37 | F9: =E9/$E$13 | G9: ='02_Volume_Price'!H37 | H9: =G9/$G$13 | I9: ='02_Volume_Price'!J37 | J9: ='02_Volume_Price'!D37-'02_Volume_Price'!C37 | K9: ='02_Volume_Price'!H37-'02_Volume_Price'!G37
B10: Clean Wipe Refill | C10: ='02_Volume_Price'!D38 | D10: =C10/$C$13 | E10: ='02_Volume_Price'!F38 | F10: =E10/$E$13 | G10: ='02_Volume_Price'!H38 | H10: =G10/$G$13 | I10: ='02_Volume_Price'!J38 | J10: ='02_Volume_Price'!D38-'02_Volume_Price'!C38 | K10: ='02_Volume_Price'!H38-'02_Volume_Price'!G38
B11: SoftSoap 3pk | C11: ='02_Volume_Price'!D39 | D11: =C11/$C$13 | E11: ='02_Volume_Price'!F39 | F11: =E11/$E$13 | G11: ='02_Volume_Price'!H39 | H11: =G11/$G$13 | I11: ='02_Volume_Price'!J39 | J11: ='02_Volume_Price'!D39-'02_Volume_Price'!C39 | K11: ='02_Volume_Price'!H39-'02_Volume_Price'!G39
B12: Multipack Snacks | C12: ='02_Volume_Price'!D40 | D12: =C12/$C$13 | E12: ='02_Volume_Price'!F40 | F12: =E12/$E$13 | G12: ='02_Volume_Price'!H40 | H12: =G12/$G$13 | I12: ='02_Volume_Price'!J40 | J12: ='02_Volume_Price'!D40-'02_Volume_Price'!C40 | K12: ='02_Volume_Price'!H40-'02_Volume_Price'!G40
B13: Total | C13: =SUM(C7:C12) | D13: =1 | E13: =SUM(E7:E12) | F13: =1 | G13: =SUM(G7:G12) | H13: =1 | I13: =IF(E13=0,0,G13/E13) | J13: =SUM(J7:J12) | K13: =SUM(K7:K12)
B15: By Channel
B16: Channel | C16: Vol Curr | D16: Vol Mix % | E16: Rev Curr $000 | F16: Rev Mix % | G16: GM Curr $000 | H16: CM $/unit | I16: GM % | J16: Vol Mix Δ pts | K16: Callout
B17: Grocery | C17: ='02_Volume_Price'!D46 | D17: =C17/$C$21 | E17: ='02_Volume_Price'!F46 | F17: =E17/$E$21 | G17: ='02_Volume_Price'!H46 | H17: =IF(C17=0,0,G17/C17) | I17: ='02_Volume_Price'!J46 | J17: ='02_Volume_Price'!L46-'02_Volume_Price'!K46 | K17: Highest margin channel; share down
B18: Mass | C18: ='02_Volume_Price'!D47 | D18: =C18/$C$21 | E18: ='02_Volume_Price'!F47 | F18: =E18/$E$21 | G18: ='02_Volume_Price'!H47 | H18: =IF(C18=0,0,G18/C18) | I18: ='02_Volume_Price'!J47 | J18: ='02_Volume_Price'!L47-'02_Volume_Price'!K47 | K18: Mid margin; mild share dip
B19: Club | C19: ='02_Volume_Price'!D48 | D19: =C19/$C$21 | E19: ='02_Volume_Price'!F48 | F19: =E19/$E$21 | G19: ='02_Volume_Price'!H48 | H19: =IF(C19=0,0,G19/C19) | I19: ='02_Volume_Price'!J48 | J19: ='02_Volume_Price'!L48-'02_Volume_Price'!K48 | K19: Mix headwind — share up, thin CM
B20: E-comm | C20: ='02_Volume_Price'!D49 | D20: =C20/$C$21 | E20: ='02_Volume_Price'!F49 | F20: =E20/$E$21 | G20: ='02_Volume_Price'!H49 | H20: =IF(C20=0,0,G20/C20) | I20: ='02_Volume_Price'!J49 | J20: ='02_Volume_Price'!L49-'02_Volume_Price'!K49 | K20: Premium price; growing share
B21: Total | C21: =SUM(C17:C20) | D21: =1 | E21: =SUM(E17:E20) | F21: =1 | G21: =SUM(G17:G20) | H21: =IF(C21=0,0,G21/C21) | I21: =IF(E21=0,0,G21/E21) | J21: =0
B23: Contribution insight
B24: Club volume mix rises while CM $/unit stays the lowest of the four channels. Multipack Snacks (Club-heavy) also gains share at thin margin. Net: positive volume on the GM bridge, negative mix — classic CPG dilution when club packs outgrow core.

Sheet 05_Dashboard
B2: Margin & Mix Dashboard
B3: ="Close: "&'01_Assumptions'!C5
B5: Headline KPIs | E5: Gross margin $ walk
B6: Metric | C6: Value | E6: Step | F6: $000s
B7: Vol Prior (000) | C7: ='03_PVM_Bridge'!C34 | E7: Prior GM | F7: ='03_PVM_Bridge'!C62
B8: Vol Curr (000) | C8: ='03_PVM_Bridge'!C35 | E8: Volume | F8: ='03_PVM_Bridge'!C63
B9: Δ Volume | C9: ='03_PVM_Bridge'!C35-'03_PVM_Bridge'!C34 | E9: Price | F9: ='03_PVM_Bridge'!C64
B10: Rev Prior $000 | C10: ='03_PVM_Bridge'!I31 | E10: Mix | F10: ='03_PVM_Bridge'!C65
B11: Rev Curr $000 | C11: ='03_PVM_Bridge'!J31 | E11: Cost | F11: ='03_PVM_Bridge'!C66
B12: GM Prior $000 | C12: ='03_PVM_Bridge'!K31 | E12: Current GM | F12: ='03_PVM_Bridge'!C67
B13: GM Curr $000 | C13: ='03_PVM_Bridge'!L31
B14: GM % Prior | C14: ='03_PVM_Bridge'!C71
B15: GM % Curr | C15: ='03_PVM_Bridge'!C72
B16: Δ GM pts | C16: ='03_PVM_Bridge'!C73
B18: RAG — Gross margin %
B19: Target GM % | C19: 0.54
B20: Actual GM % (curr) | C20: ='03_PVM_Bridge'!C72
B21: Status | C21: =IF(C20>=C19,"GREEN",IF(C20>=C19-0.02,"AMBER","RED"))
B23: Top mix-shift callouts
B24: Callout | C24: Signal
B25: Club vol mix ↑ | C25: Lower CM $/unit channel gaining share → mix headwind on GM$
B26: Multipack Snacks ↑ | C26: Club-oriented SKU grows fastest; thin contribution
B27: Grocery vol soft | C27: Highest-price channel loses units → adverse mix & price
B28: Price (Groc/Mass) | C28: Net price down ~$0.10–0.20/unit on core channels
B29: Volume overall ↑ | C29: Units up, but not enough to offset mix + price on GM$
B31: Leadership read
B32: Volume is up, but gross margin dollars and margin rate are down. The bridge pins the miss on Mix (Club / Multipack) and Price — not cost. Action lens: protect Grocery/Mass net price, rebalance Club pack architecture, or raise Club list to defend contribution.

Sheet 06_Data_Dictionary
B2: Data Dictionary
B3: Field definitions for the margin & mix bridge workbook.
B5: Field | C5: Unit / type | D5: Definition
B6: Close period | C6: Text | D6: Prior vs current comparison label (e.g. FY26 Q2 vs Q1)
B7: Channel | C7: Category | D7: Grocery, Mass, Club, E-comm — route-to-market
B8: SKU | C8: Category | D8: Sellable consumer unit / pack (6 sample Northline items)
B9: Volume | C9: 000 units | D9: Cases/units sold in the period (thousands)
B10: Net price | C10: $/unit | D10: Average realized net selling price after trade
B11: Std COGS | C11: $/unit | D11: Standard cost per unit; held flat in this sample
B12: Revenue | C12: $000s | D12: Volume (000) × net price $/unit
B13: Gross margin $ | C13: $000s | D13: Volume × (net price − std COGS)
B14: GM % | C14: % | D14: Gross margin $ ÷ revenue
B15: Contribution / CM | C15: $ or % | D15: Same as GM here (no below-gross selling cost allocated)
B16: Volume effect | C16: $000s | D16: (V1−V0) × prior blended price or margin/unit
... B22: Yellow / blue cells | C22: Input | D22: Editable assumptions; do not overwrite black formulas
B25: Fictional sample for portfolio use only. Not real company, employer, or client data.
